Workbook

Sheet Skaitykite pirma
A1: Strateginio tyrimo žiniasklaidos ir viešųjų šaltinių stebėsenos sąrašas
A3: Paskirtis
A4: Sąrašas skirtas VK strateginio tyrimo analitikams, stebintiems viešąją informaciją pagal pasiskirstytas viešojo valdymo sritis, ir gali būti naudojamas kaip pirminis šaltinių registras automatiniam naujienų rinkimui.
A6: Kaip pildyti
A7: Geltonai pažymėti ir mėlynu šriftu rašomi stulpeliai (F, I, J, K) yra skirti pildyti Jums. Kiti stulpeliai yra parengtas turinys – juos keiskite tik patikslinę informaciją.
A8: F stulpelis – RSS arba prenumeratos adresas. Dauguma rajoninių laikraščių veikia „WordPress“ pagrindu, todėl srautas paprastai yra adresu su galūne /feed/. lrv.lt domeno institucijos siūlo naujienų prenumeratą el. paštu.
A9: I stulpelis – atsakingas analitikas. Rekomenduojama priskirti pagal viešojo valdymo sritį (D stulpelis), o ne pagal šaltinio tipą.
A10: J stulpelis – ar šaltinis įtrauktas į nuolatinę stebėseną (Taip / Ne / Vertinama).
A11: K stulpelis – paskutinės peržiūros data. Padeda matyti, ar srautas tikrai stebimas.
A13: Stulpelis „Adresas patikrintas 2026-09-03“
A14: „Taip“ – adresas patikrintas oficialiame šaltinyje (lrv.lt ministerijų sąraše, NRMLLA narių sąraše arba paties leidinio puslapyje).
A15: „Tikrinti“ – adresas nurodytas iš bendrųjų žinių ir turi būti patikrintas prieš įtraukiant į automatinį rinkimą.
... A24: Sąrašas sudarytas 2026-09-03.

Sheet Šaltiniai
A1: Nr. | B1: Kategorija | C1: Šaltinio pavadinimas | D1: Viešojo valdymo sritis | E1: URL | F1: RSS / prenumeratos adresas | G1: Adresas patikrintas 2026-09-03 | H1: Rekomenduojamas stebėjimo dažnumas | I1: Atsakingas analitikas | J1: Įtraukta į stebėseną | K1: Paskutinis peržiūros įrašas | L1: Pastabos
A2: 1 | B2: 1. Nacionalinė žiniasklaida | C2: LRT | D2: Visos sritys | E2: https://www.lrt.lt/ | G2: Taip | H2: Kasdien | L2: Visuomeninis transliuotojas; atskiras tyrimų skyrius – daug medžiagos apie viešųjų lėšų naudojimą
A3: 2 | B3: 1. Nacionalinė žiniasklaida | C3: LRT Tyrimai (rubrika) | D3: Visos sritys | E3: https://www.lrt.lt/tema/lrt-tyrimai | G3: Tikrinti | H3: Kas savaitę | L3: Rubrikos adresas gali keistis – patikrinti prieš įtraukiant į automatinį rinkimą
A4: 3 | B4: 1. Nacionalinė žiniasklaida | C4: Delfi | D4: Visos sritys | E4: https://www.delfi.lt/ | G4: Taip | H4: Kasdien | L4: Didžiausia auditorija, plati regionų korespondentų aprėptis
A5: 4 | B5: 1. Nacionalinė žiniasklaida | C5: 15min | D5: Visos sritys | E5: https://www.15min.lt/ | G5: Taip | H5: Kasdien | L5: Analitiniai ir tiriamieji tekstai, aiškiai išskirtos viešosios politikos temos
A6: 5 | B6: 1. Nacionalinė žiniasklaida | C6: Lrytas | D6: Visos sritys | E6: https://www.lrytas.lt/ | G6: Taip | H6: Kasdien | L6: Didelė aprėptis, daug savivaldos ir socialinių temų
A7: 6 | B7: 1. Nacionalinė žiniasklaida | C7: TV3 | D7: Visos sritys | E7: https://www.tv3.lt/ | G7: Taip | H7: Kasdien | L7: Komercinio transliuotojo naujienos, laidos su tyrimų elementu
A8: 7 | B8: 1. Nacionalinė žiniasklaida | C8: Alfa | D8: Visos sritys | E8: https://www.alfa.lt/ | G8: Taip | H8: Kas savaitę | L8: Alternatyvus redakcinis požiūris – naudinga temų įvairovei
A9: 8 | B9: 1. Nacionalinė žiniasklaida | C9: ELTA | D9: Visos sritys | E9: https://www.elta.lt/ | G9: Taip | H9: Kasdien | L9: Naujienų agentūra – pirminis, neredaguotas įvykių srautas
A10: 9 | B10: 1. Nacionalinė žiniasklaida | C10: BNS spaudos centras | D10: Visos sritys | E10: https://sc.bns.lt/ | G10: Taip | H10: Kasdien | L10: Nemokamai skelbiami institucijų, asociacijų ir NVO pranešimai spaudai – vienos vietos srautas
A11: 10 | B11: 1. Nacionalinė žiniasklaida | C11: Bernardinai | D11: Socialinė apsauga, kultūra | E11: https://www.bernardinai.lt/ | G11: Taip | H11: Kas savaitę | L11: Socialinės atskirties, bendruomenių, vertybinių klausimų analizė, ilgi tekstai
A12: 11 | B12: 2. Verslo ir sektorinė žiniasklaida | C12: Verslo žinios | D12: Finansai, VVĮ, viešieji pirkimai | E12: https://www.vz.lt/ | G12: Taip | H12: Kasdien | L12: Dalis turinio už mokamos sienos, antraštės ir įžangos matomos
A13: 12 | B13: 2. Verslo ir sektorinė žiniasklaida | C13: IQ | D13: Viešoji politika | E13: https://iq.lt/ | G13: Taip | H13: Kas savaitę | L13: Analitinė žurnalistika, viešosios politikos apžvalgos
... A18: 17 | B18: 3. Tiriamoji žurnalistika | C18: Atvira Klaipėda | D18: Savivalda | E18: https://www.atviraklaipeda.lt/ | G18: Taip | H18: Kas savaitę | L18: Retas atvejis, kai regione veikia tiriamojo pobūdžio portalas – savivaldos sprendimų analizė
A19: 18 | B19: 4. Regioninė žiniasklaida (didmiesčiai) | C19: Kauno diena | D19: Savivalda, Kauno regionas | E19: https://kauno.diena.lt/ | G19: Taip | H19: Kasdien
A20: 19 | B20: 4. Regioninė žiniasklaida (didmiesčiai) | C20: Klaipėda (diena.lt) | D20: Savivalda, Klaipėdos regionas | E20: https://klaipeda.diena.lt/ | G20: Taip | H20: Kasdien
A21: 20 | B21: 4. Regioninė žiniasklaida (didmiesčiai) | C21: Vakarų ekspresas | D21: Savivalda, Klaipėdos regionas | E21: https://ve.lt/ | G21: Taip | H21: Kasdien | L21: NRMLLA narys
A22: 21 | B22: 4. Regioninė žiniasklaida (didmiesčiai) | C22: Šiaulių kraštas | D22: Savivalda, Šiaulių regionas | E22: https://www.skrastas.lt/ | G22: Taip | H22: Kasdien
A23: 22 | B23: 4. Regioninė žiniasklaida (didmiesčiai) | C23: Sekundė | D23: Savivalda, Panevėžio regionas | E23: https://www.sekunde.lt/ | G23: Tikrinti | H23: Kasdien
A24: 23 | B24: 4. Regioninė žiniasklaida (didmiesčiai) | C24: Etaplius | D24: Savivalda, Šiaulių regionas | E24: https://www.etaplius.lt/ | G24: Taip | H24: Kas savaitę | L24: IŽA narys
A25: 24 | B25: 4. Regioninė žiniasklaida (didmiesčiai) | C25: Kas vyksta Kaune | D25: Savivalda, Kaunas | E25: https://kaunas.kasvyksta.lt/ | G25: Taip | H25: Kas savaitę | L25: IŽA narys
A26: 25 | B26: 4. Regioninė žiniasklaida (didmiesčiai) | C26: Made in Vilnius | D26: Savivalda, Vilnius | E26: https://madeinvilnius.lt/ | G26: Taip | H26: Kas savaitę | L26: IŽA narys
A27: 26 | B27: 4. Regioninė žiniasklaida (didmiesčiai) | C27: Alytus plius | D27: Savivalda, Alytaus regionas | E27: https://www.alytusplius.lt/ | G27: Taip | H27: Kas savaitę | L27: IŽA narys
A28: 27 | B28: 5. Regioninė žiniasklaida (rajonai) | C28: Alytaus naujienos | D28: Alytaus r. | E28: https://www.alytausnaujienos.lt/ | G28: Taip | H28: Kas savaitę | L28: NRMLLA narys
A29: 28 | B29: 5. Regioninė žiniasklaida (rajonai) | C29: Anykšta | D29: Anykščių r. | E29: https://www.anyksta.lt/ | G29: Taip | H29: Kas savaitę | L29: NRMLLA narys
A30: 29 | B30: 5. Regioninė žiniasklaida (rajonai) | C30: Banga | D30: Klaipėdos r. (Gargždai) | E30: https://gargzdai.lt/ | G30: Taip | H30: Kas savaitę | L30: NRMLLA narys
A31: 30 | B31: 5. Regioninė žiniasklaida (rajonai) | C31: Bičiulis | D31: Kelmės r. | E31: https://www.biciulis.net/ | G31: Taip | H31: Kas savaitę | L31: NRMLLA narys
A32: 31 | B32: 5. Regioninė žiniasklaida (rajonai) | C32: Elektrėnų kronika | D32: Elektrėnų sav. | E32: https://www.kronika.lt/ | G32: Taip | H32: Kas savaitę | L32: NRMLLA narys
A33: 32 | B33: 5. Regioninė žiniasklaida (rajonai) | C33: Gimtasis Rokiškis | D33: Rokiškio r. | E33: https://www.grokiskis.lt/ | G33: Taip | H33: Kas savaitę | L33: NRMLLA narys
A34: 33 | B34: 5. Regioninė žiniasklaida (rajonai) | C34: Gimtoji žemė | D34: Ukmergės r. | E34: https://www.gzeme.lt/ | G34: Taip | H34: Kas savaitę | L34: NRMLLA narys
A35: 34 | B35: 5. Regioninė žiniasklaida (rajonai) | C35: Gyvenimas | D35: Prienų r., Birštono sav. | E35: https://www.gyvenimas.eu/ | G35: Taip | H35: Kas savaitę | L35: NRMLLA narys
... A55: 54 | B55: 5. Regioninė žiniasklaida (rajonai) | C55: Vienybė | D55: Akmenės r. | E55: http://www.avienybe.lt/ | G55: Taip | H55: Kas savaitę | L55: NRMLLA narys
A56: 55 | B56: 6. Valdžios institucijos | C56: Lietuvos Respublikos Vyriausybė | D56: Visos sritys | E56: https://lrv.lt/lt/ | G56: Taip | H56: Kasdien
A57: 56 | B57: 6. Valdžios institucijos | C57: Vyriausybės posėdžiai ir pasitarimai | D57: Visos sritys | E57: https://lrv.lt/lt/posedziai/ | G57: Taip | H57: Kas savaitę | L57: Darbotvarkės rodo, kokie klausimai bus sprendžiami artimiausiu metu
A58: 57 | B58: 6. Valdžios institucijos | C58: Lietuvos Respublikos Seimas | D58: Visos sritys | E58: https://www.lrs.lt/ | G58: Taip | H58: Kasdien
A59: 58 | B59: 6. Valdžios institucijos | C59: Seimo naujienos ir pranešimai spaudai | D59: Visos sritys | E59: https://www.lrs.lt/sip/portal.show?p_r=35403&p_k=1 | G59: Taip | H59: Kasdien | L59: Įskaitant komitetų ir frakcijų pranešimus
A60: 59 | B60: 6. Valdžios institucijos | C60: Teisės aktų registras (TAR) | D60: Visos sritys | E60: https://www.e-tar.lt/ | G60: Taip | H60: Kas savaitę | L60: Priimtų teisės aktų srautas
A61: 60 | B61: 6. Valdžios institucijos | C61: Teisės aktų ir projektų paieška (e-Seimas) | D61: Visos sritys | E61: https://e-seimas.lrs.lt/ | G61: Taip | H61: Kas savaitę | L61: Registruoti projektai rodo planuojamus pokyčius anksčiau nei jie priimami
A62: 61 | B62: 6. Valdžios institucijos | C62: Respublikos Prezidentas | D62: Visos sritys | E62: https://www.lrp.lt/ | G62: Tikrinti | H62: Kas savaitę
A63: 62 | B63: 6. Valdžios institucijos | C63: Aplinkos ministerija | D63: Aplinka, statyba, būstas | E63: https://am.lrv.lt/lt/ | G63: Taip | H63: Kas savaitę | L63: Naujienos: pridėti naujienos/ prie adreso
...

Sheet Suvestinė
A1: Šaltinių suvestinė pagal kategorijas
A3: Kategorija | B3: Šaltinių skaičius | C3: Iš jų adresas patikrintas | D3: Įtraukta į stebėseną
A4: 1. Nacionalinė žiniasklaida | B4: =COUNTIF(Šaltiniai!$B$2:$B$97,$A4) -> 10 | C4: =COUNTIFS(Šaltiniai!$B$2:$B$97,$A4,Šaltiniai!$G$2:$G$97,"Taip") -> 9 | D4: =COUNTIFS(Šaltiniai!$B$2:$B$97,$A4,Šaltiniai!$J$2:$J$97,"Taip") -> 0
A5: 2. Verslo ir sektorinė žiniasklaida | B5: =COUNTIF(Šaltiniai!$B$2:$B$97,$A5) -> 4 | C5: =COUNTIFS(Šaltiniai!$B$2:$B$97,$A5,Šaltiniai!$G$2:$G$97,"Taip") -> 2 | D5: =COUNTIFS(Šaltiniai!$B$2:$B$97,$A5,Šaltiniai!$J$2:$J$97,"Taip") -> 0
A6: 3. Tiriamoji žurnalistika | B6: =COUNTIF(Šaltiniai!$B$2:$B$97,$A6) -> 3 | C6: =COUNTIFS(Šaltiniai!$B$2:$B$97,$A6,Šaltiniai!$G$2:$G$97,"Taip") -> 2 | D6: =COUNTIFS(Šaltiniai!$B$2:$B$97,$A6,Šaltiniai!$J$2:$J$97,"Taip") -> 0
A7: 4. Regioninė žiniasklaida (didmiesčiai) | B7: =COUNTIF(Šaltiniai!$B$2:$B$97,$A7) -> 9 | C7: =COUNTIFS(Šaltiniai!$B$2:$B$97,$A7,Šaltiniai!$G$2:$G$97,"Taip") -> 8 | D7: =COUNTIFS(Šaltiniai!$B$2:$B$97,$A7,Šaltiniai!$J$2:$J$97,"Taip") -> 0
A8: 5. Regioninė žiniasklaida (rajonai) | B8: =COUNTIF(Šaltiniai!$B$2:$B$97,$A8) -> 28 | C8: =COUNTIFS(Šaltiniai!$B$2:$B$97,$A8,Šaltiniai!$G$2:$G$97,"Taip") -> 28 | D8: =COUNTIFS(Šaltiniai!$B$2:$B$97,$A8,Šaltiniai!$J$2:$J$97,"Taip") -> 0
A9: 6. Valdžios institucijos | B9: =COUNTIF(Šaltiniai!$B$2:$B$97,$A9) -> 21 | C9: =COUNTIFS(Šaltiniai!$B$2:$B$97,$A9,Šaltiniai!$G$2:$G$97,"Taip") -> 20 | D9: =COUNTIFS(Šaltiniai!$B$2:$B$97,$A9,Šaltiniai!$J$2:$J$97,"Taip") -> 0
A10: 7. Kontrolė ir priežiūra | B10: =COUNTIF(Šaltiniai!$B$2:$B$97,$A10) -> 12 | C10: =COUNTIFS(Šaltiniai!$B$2:$B$97,$A10,Šaltiniai!$G$2:$G$97,"Taip") -> 9 | D10: =COUNTIFS(Šaltiniai!$B$2:$B$97,$A10,Šaltiniai!$J$2:$J$97,"Taip") -> 0
A11: 8. Analitika ir duomenys | B11: =COUNTIF(Šaltiniai!$B$2:$B$97,$A11) -> 9 | C11: =COUNTIFS(Šaltiniai!$B$2:$B$97,$A11,Šaltiniai!$G$2:$G$97,"Taip") -> 5 | D11: =COUNTIFS(Šaltiniai!$B$2:$B$97,$A11,Šaltiniai!$J$2:$J$97,"Taip") -> 0
A12: Iš viso | B12: =SUM(B4:B11) -> 96 | C12: =SUM(C4:C11) -> 83 | D12: =SUM(D4:D11) -> 0
A14: Stulpelis „Įtraukta į stebėseną“ užsipildys, kai lape „Šaltiniai“ pažymėsite J stulpelį.
